Traceback (most recent call last):
  File "/usr/lib/python3/dist-packages/urllib3/connectionpool.py", line 446, in _make_request
    six.raise_from(e, None)
  File "<string>", line 3, in raise_from
  File "/usr/lib/python3/dist-packages/urllib3/connectionpool.py", line 441, in _make_request
    httplib_response = conn.getresponse()
  File "/usr/lib/python3.10/http/client.py", line 1375, in getresponse
    response.begin()
  File "/usr/lib/python3.10/http/client.py", line 318, in begin
    version, status, reason = self._read_status()
  File "/usr/lib/python3.10/http/client.py", line 279, in _read_status
    line = str(self.fp.readline(_MAXLINE + 1), "iso-8859-1")
  File "/usr/lib/python3.10/socket.py", line 705, in readinto
    return self._sock.recv_into(b)
  File "/usr/lib/python3.10/ssl.py", line 1303, in recv_into
    return self.read(nbytes, buffer)
  File "/usr/lib/python3.10/ssl.py", line 1159, in read
    return self._sslobj.read(len, buffer)
TimeoutError: The read operation timed out

During handling of the above exception, another exception occurred:

Traceback (most recent call last):
  File "/usr/lib/python3/dist-packages/requests/adapters.py", line 439, in send
    resp = conn.urlopen(
  File "/usr/lib/python3/dist-packages/urllib3/connectionpool.py", line 756, in urlopen
    retries = retries.increment(
  File "/usr/lib/python3/dist-packages/urllib3/util/retry.py", line 532, in increment
    raise six.reraise(type(error), error, _stacktrace)
  File "/usr/lib/python3/dist-packages/six.py", line 719, in reraise
    raise value
  File "/usr/lib/python3/dist-packages/urllib3/connectionpool.py", line 700, in urlopen
    httplib_response = self._make_request(
  File "/usr/lib/python3/dist-packages/urllib3/connectionpool.py", line 448, in _make_request
    self._raise_timeout(err=e, url=url, timeout_value=read_timeout)
  File "/usr/lib/python3/dist-packages/urllib3/connectionpool.py", line 337, in _raise_timeout
    raise ReadTimeoutError(
urllib3.exceptions.ReadTimeoutError: HTTPSConnectionPool(host='api.telegram.org', port=443): Read timed out. (read timeout=25)

During handling of the above exception, another exception occurred:

Traceback (most recent call last):
  File "/home/danil/telegram_media_bot/telegram_media_bot.py", line 193, in <module>
    bot.polling()
  File "/home/danil/.local/lib/python3.10/site-packages/telebot/__init__.py", line 1189, in polling
    self.__threaded_polling(non_stop=non_stop, interval=interval, timeout=timeout, long_polling_timeout=long_polling_timeout,
  File "/home/danil/.local/lib/python3.10/site-packages/telebot/__init__.py", line 1264, in __threaded_polling
    raise e
  File "/home/danil/.local/lib/python3.10/site-packages/telebot/__init__.py", line 1225, in __threaded_polling
    polling_thread.raise_exceptions()
  File "/home/danil/.local/lib/python3.10/site-packages/telebot/util.py", line 111, in raise_exceptions
    raise self.exception_info
  File "/home/danil/.local/lib/python3.10/site-packages/telebot/util.py", line 93, in run
    task(*args, **kwargs)
  File "/home/danil/.local/lib/python3.10/site-packages/telebot/__init__.py", line 687, in __retrieve_updates
    updates = self.get_updates(offset=(self.last_update_id + 1), 
  File "/home/danil/.local/lib/python3.10/site-packages/telebot/__init__.py", line 659, in get_updates
    json_updates = apihelper.get_updates(
  File "/home/danil/.local/lib/python3.10/site-packages/telebot/apihelper.py", line 330, in get_updates
    return _make_request(token, method_url, params=payload)
  File "/home/danil/.local/lib/python3.10/site-packages/telebot/apihelper.py", line 162, in _make_request
    result = _get_req_session().request(
  File "/usr/lib/python3/dist-packages/requests/sessions.py", line 544, in request
    resp = self.send(prep, **send_kwargs)
  File "/usr/lib/python3/dist-packages/requests/sessions.py", line 657, in send
    r = adapter.send(request, **kwargs)
  File "/usr/lib/python3/dist-packages/requests/adapters.py", line 529, in send
    raise ReadTimeout(e, request=request)
requests.exceptions.ReadTimeout: HTTPSConnectionPool(host='api.telegram.org', port=443): Read timed out. (read timeout=25)
